Workbook

Sheet Executive Summary
A1: NSW Helpdesk Training Needs Analysis
A2: Assessment population | B2: 29
A3: Main finding | B3: Strong confidence in core modules, but clear development needs in Air/Sea Manifest, Certificate Utilization, and complex cross-system issues.
A4: Key operational dependency | B4: 25 of 29 reps (86%) report relying on colleagues/supervisors for guidance.
A5: Confidence caveat | B5: This is a self-assessment, not a proficiency test; validate priority gaps with QA, AHT/FCR/CSAT and ticket data.
A7: Top Findings
A8: 1 | B8: Air Manifest | C8: 96.6% show a confidence gap
C9: 14 need more knowledge
C10: 3 not confident.
A11: 2 | B11: Sea Manifest | C11: 3 not confident.
C12: 96.6% show a confidence gap
C13: 15 need more knowledge
A14: 3 | B14: Certificate Utilization | C14: 24.1% show a confidence gap; it is also the dominant long-resolution/escalation theme.
A15: 4 | B15: Form M / PAAR | C15: 13.8% show a confidence gap; frequently mentioned alongside complex submission and approval issues.
A16: 5 | B16: Knowledge dependency | C16: 86.2% rely on colleagues/supervisors; this indicates a knowledge-base/process enablement opportunity.
A19: Recommended Training Priorities
A20: Rank | B20: Training Need | C20: Priority | D20: Recommendation
A21: 1 | B21: Air & Sea Manifest | C21: Critical | D21: Build foundational knowledge + hands-on case practice.
A22: 2 | B22: Certificate Utilization & Validation | C22: Critical | D22: Troubleshooting, quantity/unit mismatches, already-utilized/linked certificates, escalation rules.
A23: 3 | B23: B'Odogwu–NSW Integration & Validation Errors | C23: High | D23: HS Code, certificate count, TIN/Tax ID, generic errors, source-of-error diagnosis.
A24: 4 | B24: Excel Consignment Template | C24: High | D24: Field-by-field guide, mandatory fields, date formatting, upload troubleshooting.
A25: 5 | B25: Form M / PAAR & Approval Issues | C25: High | D25: End-to-end process, common errors, amendment/resubmission, escalation pathways.
A26: 6 | B26: Payment & Status Reconciliation | C26: Medium | D26: Pending payment, receipt verification, gateway/NSW mismatch and escalation.
A27: 7 | B27: Knowledge Base Usage | C27: Medium | D27: Create searchable troubleshooting articles and quick-reference guides.

Sheet Supervisors Insights
A1: Based on your observation of the team, what are the top three knowledge gaps that you believe should be addressed first?
A4: Priority | B4: Knowledge Gap | C4: Why It Matters | D4: Recommended Intervention
A5: 1 | B5: Sea/Air Manifest
A6: 2 | B6: New features on the NSW Helpdesk account | C6: New features are often added to the NSW helpdesk account with the agents not knowing what they do or when to use it. | D6: Periodically train agents on the NSW Helpdesk account for new functions or send user guide explaining what this functions do and when to use them.
A7: 3

Sheet Qualitative Themes
A1: Theme | B1: Evidence in Responses | C1: What It Means | D1: Recommended Action | E1: Training / Non-Training
A2: Certificate Utilization | B2: Repeatedly identified as longest to resolve, difficult, escalated, or needing more knowledge. | C2: High operational complexity and dependency on other teams. | D2: Create troubleshooting decision tree; train on validation, quantity/unit/certificate matching and escalation. | E2: Training + process
A3: B'Odogwu–NSW validation/integration | B3: HS Code mismatches, certificate count errors, TIN/Tax ID mismatch, generic validation errors, integration issues. | C3: Reps need cross-system diagnostic capability. | D3: Build cross-system troubleshooting guide and scenario-based training. | E3: Training + system/process
A4: Excel template / upload | B4: Repeated requests for Excel template guidance, upload errors, mandatory fields, date formatting. | C4: A recurring source of customer friction and rework. | D4: Create field-by-field guide and practical exercise; standardize supported spreadsheet tool. | E4: Training + documentation
A5: Air & Sea Manifest | B5: Self-assessment shows 96.6% gap rate for both modules. | C5: Largest measured confidence gap. | D5: Run foundational module training with guided cases and job aids. | E5: Training
A6: Form M / PAAR & approvals | B6: Frequently mentioned in long-resolution and escalation responses. | C6: Process complexity and approval dependencies affect resolution time. | D6: Map end-to-end process and escalation points; train reps on what they can/cannot resolve. | E6: Training + process
A7: Payment status | B7: Pending payment, payment not reflecting, payment header issues mentioned. | C7: Reps need a consistent diagnostic/escalation path. | D7: Create payment validation checklist and escalation SLA. | E7: Training + process
A8: Knowledge-base dependency | B8: 25/29 rely on colleagues/supervisors; many requested KB articles. | C8: Knowledge is not sufficiently self-service. | D8: Prioritize searchable KB articles, FAQs and decision trees. | E8: Knowledge management
A9: Inter-team dependency | B9: Approval delays and cases requiring CL/MDA/technical teams are repeatedly described. | C9: Some resolution-time problems are structural, not knowledge deficits. | D9: Define escalation matrix, ownership, expected feedback times and customer communication rules. | E9: Non-training

Sheet Raw Data
A1: Name | B1: Last modified time | C1: How long have you been supporting NSW users? | D1: Which three NSW modules generate the highest number of customer enquiries? | E1: Which issues take the longest to resolve? | F1: Which topics do you find most difficult to explain or resolve for users? | G1: Are there any processes within the NSW platform that you are not fully confident supporting? | H1: If yes, please specify. | I1: Which issues do you frequently escalate because you are unsure of the resolution? | J1: Are there situations where you rely on another colleague, supervisor for guidance? | K1: If yes, what topics? | L1: When resolving customer issues, what resources do you currently use? | M1: If you could add one article to the Knowledge Base today, what would it be? | N1: Describe a recent customer issue that was particularly difficult to resolve. What information would have helped you resolve it more efficiently? | O1: User Registration | P1: Login & Authentication | Q1: UCR | R1: Facility Registration | S1: Application Submission | T1: Payment | U1: Certificate Utilization | V1: Form M / PAAR Processing | W1: LPCO Processing | X1: Air Manifest | Y1: Sea Manifest
A2: Atuke Onoriode | C2: 6–12 months | D2: Payment;Certificate Utilization;Form M / PAAR; | E2: Certificate Utilization | F2: Uploading Excel sheet on a company Laptop of a customer | G2: No | I2: non | J2: Yes | K2: Excel sheet upload, Password reset, Payment not reflecting after customer has shown receipt and other issues that need to be resolve at backend | L2: Supervisor; | O2: Very Confident | P2: Very Confident | Q2: Very Confident | R2: Very Confident | S2: Very Confident | T2: Very Confident | U2: Very Confident | V2: Very Confident | W2: Very Confident | X2: Neutral | Y2: Neutral
A3: Ifechukwu Ozuluonye | C3: 3–6 months | D3: Payment;User Registration;Form M / PAAR; | E3: FORM M and PAAR | F3: Error 405/504 gotten by clients when making applications | G3: No | I3: Error 405/504 CL related issues | J3: Yes | K3: Just clarifications of any issue at hand as the case may be, needing more insight | L3: Personal Notes;User Guide;Existing Knowledge Base;Supervisor;Escalation - CL;Previous Tickets;Research; | M3: How to use reference numbers in search of client's information, in cases where TIN number cannot always be asked of them, to avoid aggravating clients who call in for issues. | N3: A client who had issues in completing FORM M initiation on B'odogwu, it took a long while because the PC trying to attach had already expired and was not activated on NSW before it did. I felt really bad for the client as they had passed through thick and thin to get to that stage in the application. I just hoped there was a way to help resolve it, at least for the client to submit that application before moving on to get another PC from his issuer. This is how i could have helped him more efficiently, but the reality was still in our faces, he was advised to get another. | O3: Very Confident | P3: Very Confident | Q3: Very Confident | R3: Very Confident | S3: Very Confident | T3: Very Confident | U3: Very Confident | V3: Confident | W3: Confident | X3: Neutral | Y3: Neutral
A4: Thelma Ozichi | C4: 3–6 months | D4: Application Submission;LPCO;Certificate Utilization; | E4: Certificate Utilization | G4: No | I4: Certificate Utilization and LPCO | J4: No | L4: Existing Knowledge Base;User Guide;Supervisor;Previous Tickets; | M4: LPCO Processing and HS Codes | N4: A client reported that the HS Code displayed on the application submission differed from the HS Code listed in the HS Code section of the menu. Upon investigation, the issue was traced to the migration of the client's certificates from the SON portal to the National Single Window. The matter was subsequently escalated for resolution. | O4: Very Confident | P4: Very Confident | Q4: Very Confident | R4: Very Confident | S4: Very Confident | T4: Very Confident | U4: Very Confident | V4: Very Confident | W4: Very Confident | X4: Need More Knowledge | Y4: Need More Knowledge
A5: Queen Ugbebor | C5: 3–6 months | D5: Application Submission;Certificate Utilization;Form M / PAAR; | E5: Utilization and MDA Approval issues | F5: Excel data entry during consignment document application. Payment issues | G5: No | I5: Utilization issue | J5: Yes | K5: Excel data entry during consignment document application submission. | L5: Personal Notes;Supervisor;Escalation - CL; | M5: Clear and comprehensive guide explaining the purpose and expected entries for every field in the Excel template | N5: 1. Excel Data Entry During Consignment Document Application A recent customer issue that was particularly difficult to resolve involved completing the Excel template for a Consignment Document application. The challenge was that the system flagged certain fields as required even though they were not identified as mandatory in the template or instructions. This made it difficult to accurately guide customers and often resulted in repeated submission errors, causing frustration for the customer. What would have helped resolve this issue more efficiently is a clear and comprehensive guide explaining the purpose and expected entries for every field in the Excel template, including any system validations that are not obvious from the interface. This would reduce errors, improve first-contact resolution, and enhance the overall customer experience. 2. Utilization and Approval Status Issues Another challenging issue involves utilization and approval status cases. These issues often remain unresolved even after being escalated to the Customs department and NAFDAC, leaving me with limited visibility or control over the outcome. In many cases, the only option is to advise customers to contact the responsible department directly, which can delay resolution and lead to customer dissatisfaction. What would have helped is having a direct communication channel or designated point of contact within the relevant departments to facilitate faster collaboration and follow-up on escalated cases. This would enable quicker issue resolution, improve coordination between teams, and allow us to provide more timely and effective support, ensuring customers can complete their documentation with minimal delays. | O5: Very Confident | P5: Very Confident | Q5: Very Confident | R5: Very Confident | S5: Very Confident | T5: Neutral | U5: Neutral | V5: Very Confident | W5: Very Confident | X5: Not Confident | Y5: Not Confident
A6: Anthony Rufus | C6: 3–6 months | D6: Certificate Utilization;Login & Authentication;Payment; | E6: Certificate Utilization | F6: PAAR Application Submission, Certificate Utilization Issues and Application Submission | G6: No | I6: Certificate Utilization | J6: Yes | K6: Application submission and Certificate Utilization Issues | L6: Existing Knowledge Base;User Guide;Supervisor; | N6: The client was experiencing issues with quantity discrepancies, which made the client frustrated with the application process. | O6: Very Confident | P6: Very Confident | Q6: Very Confident | R6: Confident | S6: Neutral | T6: Confident | U6: Need More Knowledge | V6: Need More Knowledge | W6: Neutral | X6: Not Confident | Y6: Not Confident
A7: Blessing Obinna | C7: 3–6 months | D7: Form M / PAAR;Certificate Utilization;Payment; | E7: certificate utilization and MDA Approval | F7: Excel uploading | G7: No | I7: FORM M/PAAR | J7: Yes | K7: ITEM UPLOADING, HS CODE NOT REFLECTING, PAYMENT NOT RELFECTING AMENDMENT OF SUBMITTED APPLICATION, | L7: User Guide;Supervisor;Existing Knowledge Base; | M7: Knowledge Base Article: Appropriate Use of the Country of Origin Excel Sheet for Consignment Applications I would add an article titled "Appropriate Use of the Country of Origin Excel Sheet When Submitting Consignment Applications. | N7: A recent customer issue that was particularly difficult to resolve involved a client who had successfully activated a product certificate on the NSW portal and uploaded it to the B'Odogwu platform. However, when processing the transaction, the system displayed the error: "The items count is 1, which is greater than the certificate count 0 To resolve the issue, I first apologized for the inconvenience caused and reassured the client that the issue would be investigated. I then reviewed the application documents on the NSW platform, verified the HS Code, item description, and certificate count, and compared them with the information entered on B'Odogwu. During the review, I identified inconsistencies between the declaration details and the information on the approved certificate. I advised the client to use the HS Code and item description exactly as displayed on the NSW platform when making declarations on B'Odogwu to ensure consistency and avoid validation or processing issues. This helped resolve the issue and allowed the declaration to proceed successfully. | O7: Confident | P7: Confident | Q7: Confident | R7: Confident | S7: Confident | T7: Confident | U7: Confident | V7: Confident | W7: Confident | X7: Need More Knowledge | Y7: Need More Knowledge
A8: Kenneth Obianyo | C8: 6–12 months | D8: Form M / PAAR;Certificate Utilization;LPCO; | E8: Certificate Utilization | F8: Nil | G8: No | I8: Issues with backend or agency-related and Remita(payment providers) | J8: No | L8: Personal Notes;Existing Knowledge Base;Previous Tickets;User Guide;Supervisor;Escalation - CL; | M8: Steps to UCR creation | N8: None for now | O8: Very Confident | P8: Very Confident | Q8: Very Confident | R8: Very Confident | S8: Very Confident | T8: Very Confident | U8: Very Confident | V8: Very Confident | W8: Very Confident | X8: Neutral | Y8: Neutral
A9: Alfred Malachy | C9: 3–6 months | D9: Certificate Utilization;Form M / PAAR;Payment; | E9: Certificate Utilization | F9: Payment | G9: No | I9: Certificate Utilization | J9: Yes | K9: Company Address Discrepancy, Request for additional product – NAFDAC License, Assistance Required for SON Consignment Document Application, Inquiry on Amendment of Approved SONCAP Import Permit and Declared HS Code Does Not Align with Customs Classification | L9: Personal Notes;User Guide;Existing Knowledge Base;Supervisor;Previous Tickets;Escalation - CL; | M9: How to verify that the HS Code, quantity, and unit of measurement match across the Consignment Document, Import Permit, Form M, and B'Odogwu GOODS section. | N9: A recent difficult issue involved a customer whose payment status remained "Pending Payment" on the NSW platform despite a successful payment and bank debit. The issue required escalation to the technical team, causing delays. It would have been resolved more efficiently with a Knowledge Base article on payment validation issues, clear escalation procedures, and a way to verify payment status between the payment gateway and the NSW platform. | O9: Very Confident | P9: Very Confident | Q9: Very Confident | R9: Neutral | S9: Very Confident | T9: Very Confident | U9: Confident | V9: Confident | W9: Confident | X9: Need More Knowledge | Y9: Need More Knowledge
A10: Simon Rosemary | C10: 3–6 months | D10: Application Submission;Certificate Utilization;Login & Authentication; | E10: Certificate Utilization | F10: Excel Template | G10: No | I10: Certificate Utilization | J10: Yes | K10: Excel and some error message NSW | L10: Personal Notes; | M10: Declared HS Code alignment | N10: The client reported being unable to make payment because the Payment header was not displaying on the NSW platform. As a result, the client was unable to make payment. The request to get customer details came in late, as it was requested for escalation | O10: Confident | P10: Neutral | Q10: Very Confident | R10: Confident | S10: Confident | T10: Very Confident | U10: Very Confident | V10: Very Confident | W10: Confident | X10: Need More Knowledge | Y10: Need More Knowledge
A11: Felicia Ejoor | C11: 3–6 months | D11: Certificate Utilization;Form M / PAAR;Login & Authentication; | E11: certificate utilization | F11: certificate utilization | G11: No | I11: issues related with cl | J11: Yes | K11: issues related with cl | L11: Personal Notes;User Guide;Existing Knowledge Base;Supervisor;Escalation - CL;Previous Tickets; | M11: certificate utilization | N11: knowledge base | O11: Confident | P11: Very Confident | Q11: Very Confident | R11: Very Confident | S11: Very Confident | T11: Confident | U11: Neutral | V11: Neutral | W11: Neutral | X11: Need More Knowledge | Y11: Need More Knowledge
A12: Larry Eduwaye | C12: 3–6 months | D12: Certificate Utilization;Form M / PAAR;Payment; | E12: Issues that has to do with discrepancies in the quantities and units declared on NSW and on Bodogwu | F12: Certificate Utilization Issues and issues with application pending approvals | G12: No | I12: Issues with clients experiencing the org,hibernate error message while trying to summit consignment document on NSW | J12: Yes | K12: Payment receipt issues, Amendment or query resubmission | L12: Personal Notes;User Guide;Supervisor; | M12: How to successfully upload excel file | N12: A customer who got the org.hibernate error message, it was very difficult to solve, as the customer has to send the reference number of her application, the reference number has to be sent to CL before the customer will be able to summit her application Though, the issue was later resolved | O12: Very Confident | P12: Very Confident | Q12: Very Confident | R12: Very Confident | S12: Very Confident | T12: Confident | U12: Neutral | V12: Confident | W12: Confident | X12: Not Confident | Y12: Not Confident
A13: Adeyemi Adedeji | C13: 3–6 months | D13: Login & Authentication;Certificate Utilization;Form M / PAAR; | E13: Custom utilization issues | F13: Use of the Excel template | G13: Yes | H13: Excel sheet template | I13: Custom utilization issues | J13: Yes | K13: Excel sheet template issues, Password reset | L13: Personal Notes;User Guide;Existing Knowledge Base;Supervisor;Escalation - CL;Previous Tickets; | M13: How to use the Excel Template | N13: Client complained of an inability to upload an Excel template with an error response: Unparseable date. Training on how to fill out the Excel template and that it's better to use Microsoft Excel than any other spreadsheet | O13: Very Confident | P13: Very Confident | Q13: Very Confident | R13: Very Confident | S13: Very Confident | T13: Very Confident | U13: Confident | V13: Confident | W13: Very Confident | X13: Neutral | Y13: Neutral
A14: Kehinde Busayo | C14: 6–12 months | D14: Certificate Utilization;LPCO;Application Submission; | E14: Certificate Utilization and Approval delays | F14: I find it most difficult to explain issues involving B'Odogwu and the National Single Window, especially validation errors such as HS Code mismatches, missing certificates, or authorization errors. | G14: No | I14: I frequently escalate issues involving MDA approval delays, B'Odogwu and NSW integration errors, and technical system glitches, as these often require investigation or resolution by the technical team or the relevant MDA rather than the Helpdesk. | J14: Yes | K14: BOdugwu complex validation errors, HS Code mismatches or not on dropdown and certificate discrepancies | L14: User Guide;Existing Knowledge Base;Escalation - CL;Personal Notes;Supervisor; | M14: A troubleshooting guide for common B'Odogwu and National Single Window integration issues, including validation errors, HS Code mismatches, and their resolutions. | N14: A recent difficult issue involved a user experiencing an HS Code mismatch between B'Odogwu and the National Single Window, which prevented the application from progressing. It would have been resolved more efficiently if there had been a knowledge base article with common validation errors, their causes, and clear troubleshooting steps, including whether the issue originated from NSW, B'Odogwu, or the relevant MDA. | O14: Very Confident | P14: Very Confident | Q14: Very Confident | R14: Very Confident | S14: Very Confident | T14: Confident | U14: Confident | V14: Confident | W14: Confident | X14: Need More Knowledge | Y14: Need More Knowledge
A15: Godwin Omotosho | C15: 3–6 months | D15: Payment;Certificate Utilization;Form M / PAAR; | E15: Custom utilization. | F15: Multiple products are involved under a single consignment. The HS Code was incorrectly selected during application submission. | G15: No | I15: There is a mismatch between system records that cannot be corrected by the user The error message is generic or does not indicate the actual cause. | J15: Yes | K15: B'odogwu errors | L15: User Guide;Supervisor;Existing Knowledge Base;Previous Tickets;Personal Notes;Escalation - CL; | M15: Prerequisites for application submission. Required documents and validation checks. Common errors encountered during submission and their resolutions. Steps for activating SONCAP and PC certificates. Reasons why certificate activation may fail. | N15: One particularly difficult customer issue involved a TIN mismatch error when a customer attempted to submit an application through B'Odogwu. The customer was using a TIN on B'Odogwu but had registered a separate account on NSW using a Tax ID. As a result, the application was submitted under the Tax ID account, while B'Odogwu was validating against the TIN account, causing the mismatch error. The challenge was identifying the root cause because the customer had two separate NSW accounts linked to different identification numbers. This required additional investigation to confirm which account contained the application and why the records were not aligning between the systems. The resolution was to have the customer transfer and upload all relevant documents from the Tax ID account to the TIN account so that the application could correctly correlate with the details on B'Odogwu. The information that would have helped resolve the issue more efficiently was earlier visibility of all customer accounts associated with both the TIN and Tax ID, as well as a clearer indication that the application had been submitted under a different account. Having this information readily available would have reduced troubleshooting time and allowed the issue to be identified and resolved much faster. | O15: Very Confident | P15: Very Confident | Q15: Very Confident | R15: Very Confident | S15: Very Confident | T15: Confident | U15: Neutral | V15: Confident | W15: Confident | X15: Need More Knowledge | Y15: Need More Knowledge
A16: Samuel Adeniji | C16: Less than 3 months | D16: Application Submission;Form M / PAAR;LPCO; | E16: Application Submission. | F16: Certificate Utilization | G16: No | I16: Issues from B'odogwu that are linked with NSW | J16: Yes | K16: Topics like: Reset Password, Change of Customer's Address and Phone number on NSW Portal | L16: User Guide;Existing Knowledge Base;Supervisor;Personal Notes; | M16: Frequent Asked Question by Customers and step by step Answers. for the benefit of the new joiners. | N16: When Country of Origin is not populating, on the item list page. Step by Step Process in resolving these issues, should be provided on the Knowledge base. | O16: Very Confident | P16: Very Confident | Q16: Very Confident | R16: Very Confident | S16: Confident | T16: Confident | U16: Neutral | V16: Confident | W16: Confident | X16: Neutral | Y16: Neutral
A17: Elizabeth Echanah | C17: 6–12 months | D17: Application Submission;Certificate Utilization;Login & Authentication; | E17: Utilization issues | F17: Utilization issues and approval for a fresh application and supplementary approval are hard to resolve, and users don't want to understand even when you explain. | G17: No | I17: Utilization, quantity and hscode | J17: Yes | K17: Utilization, quantity | L17: Personal Notes;Supervisor;Existing Knowledge Base;Previous Tickets;hands on practise on the testing environment;Escalation - CL; | M17: Differences and relationship between MD & CD - PC & SC | N17: Discrepancy between MD CD - PC SC. The user was trying to reference a PC number to a consignment document, which is not possible. I was trying to clarify because I knew what the issue was about, but user was holding on to his complaint even when the fact was obvious. I was able to resolve it with the assistance from my supervisor, who still explained same thing to the user. | O17: Very Confident | P17: Very Confident | Q17: Very Confident | R17: Very Confident | S17: Very Confident | T17: Very Confident | U17: Confident | V17: Neutral | W17: Very Confident | X17: Neutral | Y17: Neutral
A18: Larry Eduwaye | C18: 3–6 months | D18: Application Submission;Certificate Utilization;LPCO; | E18: certificate utilization issues | F18: certificate utilization issues | G18: No | I18: certificate utilization issues | J18: Yes | K18: it varies | L18: Existing Knowledge Base;Personal Notes;Supervisor; | M18: certificate utilization | N18: i don't have any | O18: Very Confident | P18: Very Confident | Q18: Very Confident | R18: Very Confident | S18: Very Confident | T18: Very Confident | U18: Confident | V18: Confident | W18: Very Confident | X18: Need More Knowledge | Y18: Need More Knowledge
A19: Alice Attah | C19: 3–6 months | D19: Certificate Utilization;Form M / PAAR;Payment; | E19: Certificate utilazation | F19: Form M/paar | G19: No | I19: Certificate utilazation | J19: Yes | K19: Form M/paar | L19: Existing Knowledge Base; | O19: Very Confident | P19: Very Confident | Q19: Very Confident | R19: Very Confident | S19: Very Confident | T19: Confident | U19: Confident | V19: Confident | W19: Very Confident | X19: Confident | Y19: Neutral
A20: Rosemary Nnaji | C20: 3–6 months | D20: Form M / PAAR;Certificate Utilization;LPCO; | E20: Kindly note that the issues that typically take the longest to resolve are those relating to Licenses Permits Certificates and Others (LPCO), Form M / PAAR, Certificate Utitization. | F20: The issue I find most difficult to explain or resolve is the Excel sheet related issue encountered during the application process. | G20: No | I20: The issue I frequently escalate is the inability to upload the Excel sheet under the Item Header section. | J20: Yes | K20: The Excel sheet section of the application process is an area where I often seek guidance and assistance from my colleagues and supervisor. | L20: Existing Knowledge Base; | M20: If I were to add one article to the knowledge base today, I would add an article on how to troubleshoot and resolve Excel sheet related issues encountered during the application process. | N20: The issue involves a customer who was applying for a Consignment Document. After selecting the country of origin as Indonesia, the customer discovered that the Port of Departure (Patimban Port) was not available on the NSW portal. It is recommended that the NSW team add Patimban Port to the list of available ports on the NSW platform and liaise with the Customs to ensure the port is also added on their end. | O20: Confident | P20: Confident | Q20: Confident | R20: Confident | S20: Confident | T20: Confident | U20: Confident | V20: Confident | W20: Confident | X20: Need More Knowledge | Y20: Need More Knowledge
A21: Gbaden Aondohemba | C21: 3–6 months | D21: Certificate Utilization;Form M / PAAR;LPCO; | E21: Document Item and Quantity issues. | F21: Most times it comes down to trying to explain to customers how the item and quantity fields work. They tend to knowingly or unknowingly input higher numbers or descriptions. | G21: No | I21: Payment issues definitely. This has to do with the user`s money and one might pass the wrong information to users, which might faulter the application. | J21: Yes | K21: User Registrations (email updates), Payment redemptions. | L21: Personal Notes;User Guide;Supervisor;Escalation - CL; | M21: NIL | N21: That would be an issue where a migrated SON import permit certificate was integrated to NSW with wrong HS codes according to the user. Issue was escalated and it is still being worked as at this time I filled this form. | O21: Very Confident | P21: Very Confident | Q21: Very Confident | R21: Very Confident | S21: Very Confident | T21: Very Confident | U21: Confident | V21: Confident | W21: Very Confident | X21: Neutral | Y21: Confident
A22: Ruth Dickson | C22: 3–6 months | D22: Certificate Utilization;Payment;Application Submission; | E22: Certificate Utilization | F22: The difficulties come from customers' inability to understand HS CODE ITEM COUNT ERRORS & QUANTITY ERRORS associated with B'odogwu validation errors | G22: No | I22: Master document / Consignment document failures due to technical issues | J22: Yes | K22: Technical issues that needs the CL teams | L22: Personal Notes;Existing Knowledge Base;Supervisor; | M22: Guidelines on how to attend to issues Basically, articles on do's and don'ts when we agents are attending to tickets. | N22: A customer was having issues understanding the B'odogw validation error message about the quantity being declared on B'odogwu being different from the quantity he was declaring on B'odogwu. He was informed that all quantities filled must be in sync, and he kept on arguing that it had never been that way. After sending a series of messages and he was not understanding, I had to call him to verbally explain things to him, which he eventually understood, and his concerns were resolved. | O22: Very Confident | P22: Very Confident | Q22: Very Confident | R22: Very Confident | S22: Very Confident | T22: Very Confident | U22: Very Confident | V22: Very Confident | W22: Very Confident | X22: Need More Knowledge | Y22: Need More Knowledge
A23: Justina Anazia | C23: 3–6 months | D23: User Registration;Application Submission;Certificate Utilization; | E23: Certificate Utilization | F23: Bodogwu ERROR MESSAGES | G23: Yes | H23: Bodogwu ERROR MESSAGES | I23: Bodogwu Error message | J23: No | L23: Personal Notes;Escalation - CL;Supervisor;Existing Knowledge Base;User Guide;Previous Tickets; | M23: nil | N23: The customer reported that after making payment via bank transfer using the generated RRR, the payment was successful. However, the NSW platform generated a different RRR for another payment instead of updating the original transaction. | O23: Very Confident | P23: Very Confident | Q23: Very Confident | R23: Very Confident | S23: Very Confident | T23: Need More Knowledge | U23: Neutral | V23: Neutral | W23: Neutral | X23: Need More Knowledge | Y23: Need More Knowledge
A24: Esihegbeme Ogedegbe | C24: 3–6 months | D24: Form M / PAAR;Application Submission;Login & Authentication; | E24: Certificate Utilization and LPCO approval | F24: Sea manifest | G24: No | I24: NIL | J24: Yes | K24: NSW server error | L24: My saved template; | M24: NIL | N24: I handled a issue where B'Odogwu required a SONCAP certificate for an HS Code that is not classified under SON on the NSW portal. Having a synchronized database between NSW and B'Odogwu showing real-time regulatory mappings for HS Codes would have helped clarify and resolve the discrepancy faster. | O24: Very Confident | P24: Very Confident | Q24: Very Confident | R24: Very Confident | S24: Very Confident | T24: Very Confident | U24: Very Confident | V24: Very Confident | W24: Very Confident | X24: Neutral | Y24: Need More Knowledge
A25: Divine Samuel | C25: 3–6 months | D25: Certificate Utilization;Login & Authentication;Application Submission; | E25: certificate utilization | F25: Excel Templet | G25: No | I25: Certificate utilization | J25: Yes | K25: Excel Templet | L25: Personal Notes; | M25: Kindly ensure that the HS Code and item count on your National Single Window (NSW) permit exactly match the information declared on the B'Odogwu platform to avoid any discrepancies. | N25: Excel Templet | O25: Very Confident | P25: Very Confident | Q25: Very Confident | R25: Very Confident | S25: Very Confident | T25: Very Confident | U25: Confident | V25: Very Confident | W25: Very Confident | X25: Need More Knowledge | Y25: Need More Knowledge
A26: Abisola Babatunde | C26: 3–6 months | D26: Login & Authentication;Form M / PAAR;Payment; | E26: system error messages, application processing errors, and cases requiring technical investigation. | F26: The topics I find most difficult to explain or resolve for users are issues involving system error messages, their solutions in the Knowledge Base would improve troubleshooting efficiency and enable quicker support for users. | G26: No | I26: The issues I frequently escalate are those related to unclear system error messages, common error messages with their solutions in the Knowledge Base would help improve first-level resolution and reduce dependency on escalation. | J26: No | L26: Personal Notes;User Guide;Supervisor;Existing Knowledge Base;Previous Tickets;Escalation - CL; | M26: If I could add one article to the Knowledge Base today, it would be a comprehensive troubleshooting guide for common National Single Window (NSW) application errors. The article would include common error messages, their possible causes, recommended resolutions, and the information customers should provide when reporting an issue, such as screenshots, reference numbers, and the steps performed before the error occurred. This would enable support agents to resolve issues more quickly, reduce unnecessary escalations, ensure consistent responses, and improve the overall customer experience. | N26: A recent customer issue that was particularly difficult to resolve involved an application error on the National Single Window (NSW) platform. The customer stated the issue but initially did not provide a screenshot of the error message, making it difficult to identify the root cause or determine the appropriate troubleshooting steps. | O26: Very Confident | P26: Very Confident | Q26: Very Confident | R26: Very Confident | S26: Very Confident | T26: Confident | U26: Confident | V26: Very Confident | W26: Confident | X26: Need More Knowledge | Y26: Need More Knowledge
A27: Emmanuel Ekpete | C27: 3–6 months | D27: Application Submission;Form M / PAAR;LPCO; | E27: The issues that take the longest to resolve are typically certificate utilization/validation issues, LPCO-related issues, and Form M/PAAR validation or linkage issues, especially when they require investigation or intervention by the technical team, NAFDAC, SON, or Nigeria Customs Service. | F27: The topics I find most difficult to explain or resolve are certificate utilization issues, particularly cases where a certificate is reported as already utilized, incorrectly linked to another application, or unavailable for a new Form M/PAAR application, as these often require further investigation and technical intervention. | G27: Yes | H27: Yes. I am not fully confident with certificate utilization/validation issues, particularly when a certificate is flagged as already utilized or linked to another application. These cases cannot always be resolved directly by the support team and often need to be escalated to the relevant technical team or MDA for investigation. This means the client may have to wait for feedback before the issue can be resolved, and the turnaround time can sometimes be lengthy. | I27: I frequently escalate certificate utilization and validation issues, especially cases where a certificate is flagged as already utilized, incorrectly linked to another application, or unavailable for Form M/PAAR processing. These cases often require technical investigation or intervention from the relevant MDA or technical team, so they cannot always be resolved directly at the support level. | J27: Yes | K27: Yes. I sometimes rely on a colleague or supervisor for guidance, particularly when handling HS Code discrepancies or mismatches, such as cases where the HS Code declared by the client does not align with the agency permit, certificate, or Customs requirements. These cases can require additional clarification or confirmation to ensure the correct HS Code is applied before advising the client. | L27: Personal Notes;Previous Tickets;Existing Knowledge Base;Supervisor;User Guide; | M27: If I could add one article to the Knowledge Base today, it would be a comprehensive troubleshooting guide for Certificate Utilization and Validation Issues and HS Code discrepancies. It should include common error messages, causes, step-by-step resolution procedures, when to escalate, and the required information to obtain from clients for escalation. | N27: A recent difficult issue involved a certificate utilization/validation error, where a client received a message that the certificate had already been used in another application, even though the client confirmed that it had never been used before. The issue was difficult to resolve because it required technical investigation and validation by the relevant MDA, rather than a resolution that could be provided directly by customer support. The client therefore had to wait for feedback, which extended the resolution time. It would have helped to resolve the issue more efficiently if we had clear visibility into the certificate’s utilization history, including the application/reference number where it was allegedly used, the certificate status, and relevant validation logs. This would make it easier to identify the cause and provide a quicker resolution. | O27: Very Confident | P27: Very Confident | Q27: Very Confident | R27: Very Confident | S27: Very Confident | T27: Very Confident | U27: Very Confident | V27: Very Confident | W27: Very Confident | X27: Need More Knowledge | Y27: Need More Knowledge
A28: Blessing Acha | C28: 6–12 months | D28: Certificate Utilization;Payment;Form M / PAAR; | E28: Certificate Utilization | G28: No | I28: Certificate Utilization on Bodogwu | J28: Yes | K28: All topic, for clarity purpose and also providing cx with the right information | L28: Personal Notes;User Guide;Existing Knowledge Base;Supervisor;Escalation - CL; | O28: Very Confident | P28: Very Confident | Q28: Very Confident | R28: Very Confident | S28: Very Confident | T28: Very Confident | U28: Confident | V28: Confident | W28: Very Confident | X28: Neutral | Y28: Neutral
A29: Glory Ezeji | C29: 6–12 months | D29: Login & Authentication;Application Submission;Certificate Utilization; | E29: Certificate Utilization | F29: NAFDAC Consignment Excel Upload | G29: No | I29: NSW Error, Certificate Utilization. | J29: Yes | K29: NSW Error, Excel for NAFDAC Consignment, Migration Error | L29: Personal Notes;Supervisor;User Guide; | M29: User Guide for NAFDAC Consignment Excel Upload | N29: Certificate Utilization for FORM M. If the work around was communicated earlier to enable us provide faster resolution to customers. | O29: Very Confident | P29: Very Confident | Q29: Very Confident | R29: Very Confident | S29: Confident | T29: Very Confident | U29: Confident | V29: Confident | W29: Confident | X29: Neutral | Y29: Neutral
A30: Hamza Nanajuwairriya | C30: 3–6 months | D30: Application Submission;User Registration;Payment; | E30: The excel upload errors as well as the certificate validations on b'odogwu | F30: None yet | G30: No | I30: Hs codes related issues | J30: Yes | K30: Hs codes related issues | L30: Existing Knowledge Base;User Guide;Supervisor; | M30: Decoding B’odogwu vague errors: A quick reference guide for common cryptic error messages and their easy resolutions. | N30: One of the most challenging customer issues I’ve had to resolve recently involved Chapter 99 HS codes. A client urgently needed these codes to be available on National Single Window for their import documentation, but they discovered that Chapter 99 wasn’t listed there. At first, the term itself was strange to me, Chapter 99 is a special section of the Harmonized System (HS) used for temporary provisions, exemptions, or trade remedies. Because it’s not commonly used, it wasn’t immediately clear why it wasn’t showing up in the system. The client was under pressure, and I had to escalate quickly. Knowing beforehand that Chapter 99 HS codes can sometimes be visible on B’odogwu but not on National Single Window would have made a huge difference in resolving that case more efficiently. If I had that information upfront, I could have: Explained the discrepancy to the client immediately instead of spending time searching for the codes myself. Escalated faster to the right supervisors to assist in resolving the case. | O30: Very Confident | P30: Very Confident | Q30: Very Confident | R30: Very Confident | S30: Very Confident | T30: Very Confident | U30: Very Confident | V30: Very Confident | W30: Very Confident | X30: Neutral | Y30: Neutral

Sheet Module Analysis
A1: Module | B1: Very Confident | C1: Confident | D1: Neutral | E1: Need More Knowledge | F1: Not Confident | G1: Avg Score | H1: Gap Rate | I1: Priority
A2: User Registration | B2: =COUNTIF('Raw Data'!$O$2:$O$30,"Very Confident") -> 25 | C2: =COUNTIF('Raw Data'!$O$2:$O$30,"Confident") -> 4 | D2: =COUNTIF('Raw Data'!$O$2:$O$30,"Neutral") -> 0 | E2: =COUNTIF('Raw Data'!$O$2:$O$30,"Need More Knowledge") -> 0 | F2: =COUNTIF('Raw Data'!$O$2:$O$30,"Not Confident") -> 0 | G2: =IFERROR((B2*4+C2*3+D2*2+(E2+F2)*1)/COUNTA('Raw Data'!$O$2:$O$30),0) -> 3.862069 | H2: =IFERROR((D2+E2+F2)/COUNTA('Raw Data'!$O$2:$O$30),0) -> 0 | I2: =IF(H2>=0.6,"Critical",IF(H2>=0.4,"High",IF(H2>=0.2,"Medium","Low"))) -> Low
A3: Login & Authentication | B3: =COUNTIF('Raw Data'!$P$2:$P$30,"Very Confident") -> 26 | C3: =COUNTIF('Raw Data'!$P$2:$P$30,"Confident") -> 2 | D3: =COUNTIF('Raw Data'!$P$2:$P$30,"Neutral") -> 1 | E3: =COUNTIF('Raw Data'!$P$2:$P$30,"Need More Knowledge") -> 0 | F3: =COUNTIF('Raw Data'!$P$2:$P$30,"Not Confident") -> 0 | G3: =IFERROR((B3*4+C3*3+D3*2+(E3+F3)*1)/COUNTA('Raw Data'!$P$2:$P$30),0) -> 3.862069 | H3: =IFERROR((D3+E3+F3)/COUNTA('Raw Data'!$P$2:$P$30),0) -> 0.034482759 | I3: =IF(H3>=0.6,"Critical",IF(H3>=0.4,"High",IF(H3>=0.2,"Medium","Low"))) -> Low
A4: UCR | B4: =COUNTIF('Raw Data'!$Q$2:$Q$30,"Very Confident") -> 27 | C4: =COUNTIF('Raw Data'!$Q$2:$Q$30,"Confident") -> 2 | D4: =COUNTIF('Raw Data'!$Q$2:$Q$30,"Neutral") -> 0 | E4: =COUNTIF('Raw Data'!$Q$2:$Q$30,"Need More Knowledge") -> 0 | F4: =COUNTIF('Raw Data'!$Q$2:$Q$30,"Not Confident") -> 0 | G4: =IFERROR((B4*4+C4*3+D4*2+(E4+F4)*1)/COUNTA('Raw Data'!$Q$2:$Q$30),0) -> 3.9310345 | H4: =IFERROR((D4+E4+F4)/COUNTA('Raw Data'!$Q$2:$Q$30),0) -> 0 | I4: =IF(H4>=0.6,"Critical",IF(H4>=0.4,"High",IF(H4>=0.2,"Medium","Low"))) -> Low
A5: Facility Registration | B5: =COUNTIF('Raw Data'!$R$2:$R$30,"Very Confident") -> 24 | C5: =COUNTIF('Raw Data'!$R$2:$R$30,"Confident") -> 4 | D5: =COUNTIF('Raw Data'!$R$2:$R$30,"Neutral") -> 1 | E5: =COUNTIF('Raw Data'!$R$2:$R$30,"Need More Knowledge") -> 0 | F5: =COUNTIF('Raw Data'!$R$2:$R$30,"Not Confident") -> 0 | G5: =IFERROR((B5*4+C5*3+D5*2+(E5+F5)*1)/COUNTA('Raw Data'!$R$2:$R$30),0) -> 3.7931034 | H5: =IFERROR((D5+E5+F5)/COUNTA('Raw Data'!$R$2:$R$30),0) -> 0.034482759 | I5: =IF(H5>=0.6,"Critical",IF(H5>=0.4,"High",IF(H5>=0.2,"Medium","Low"))) -> Low
A6: Application Submission | B6: =COUNTIF('Raw Data'!$S$2:$S$30,"Very Confident") -> 23 | C6: =COUNTIF('Raw Data'!$S$2:$S$30,"Confident") -> 5 | D6: =COUNTIF('Raw Data'!$S$2:$S$30,"Neutral") -> 1 | E6: =COUNTIF('Raw Data'!$S$2:$S$30,"Need More Knowledge") -> 0 | F6: =COUNTIF('Raw Data'!$S$2:$S$30,"Not Confident") -> 0 | G6: =IFERROR((B6*4+C6*3+D6*2+(E6+F6)*1)/COUNTA('Raw Data'!$S$2:$S$30),0) -> 3.7586207 | H6: =IFERROR((D6+E6+F6)/COUNTA('Raw Data'!$S$2:$S$30),0) -> 0.034482759 | I6: =IF(H6>=0.6,"Critical",IF(H6>=0.4,"High",IF(H6>=0.2,"Medium","Low"))) -> Low
A7: Payment | B7: =COUNTIF('Raw Data'!$T$2:$T$30,"Very Confident") -> 17 | C7: =COUNTIF('Raw Data'!$T$2:$T$30,"Confident") -> 10 | D7: =COUNTIF('Raw Data'!$T$2:$T$30,"Neutral") -> 1 | E7: =COUNTIF('Raw Data'!$T$2:$T$30,"Need More Knowledge") -> 1 | F7: =COUNTIF('Raw Data'!$T$2:$T$30,"Not Confident") -> 0 | G7: =IFERROR((B7*4+C7*3+D7*2+(E7+F7)*1)/COUNTA('Raw Data'!$T$2:$T$30),0) -> 3.4827586 | H7: =IFERROR((D7+E7+F7)/COUNTA('Raw Data'!$T$2:$T$30),0) -> 0.068965517 | I7: =IF(H7>=0.6,"Critical",IF(H7>=0.4,"High",IF(H7>=0.2,"Medium","Low"))) -> Low
A8: Certificate Utilization | B8: =COUNTIF('Raw Data'!$U$2:$U$30,"Very Confident") -> 9 | C8: =COUNTIF('Raw Data'!$U$2:$U$30,"Confident") -> 13 | D8: =COUNTIF('Raw Data'!$U$2:$U$30,"Neutral") -> 6 | E8: =COUNTIF('Raw Data'!$U$2:$U$30,"Need More Knowledge") -> 1 | F8: =COUNTIF('Raw Data'!$U$2:$U$30,"Not Confident") -> 0 | G8: =IFERROR((B8*4+C8*3+D8*2+(E8+F8)*1)/COUNTA('Raw Data'!$U$2:$U$30),0) -> 3.0344828 | H8: =IFERROR((D8+E8+F8)/COUNTA('Raw Data'!$U$2:$U$30),0) -> 0.24137931 | I8: =IF(H8>=0.6,"Critical",IF(H8>=0.4,"High",IF(H8>=0.2,"Medium","Low"))) -> Medium
A9: Form M / PAAR Processing | B9: =COUNTIF('Raw Data'!$V$2:$V$30,"Very Confident") -> 11 | C9: =COUNTIF('Raw Data'!$V$2:$V$30,"Confident") -> 14 | D9: =COUNTIF('Raw Data'!$V$2:$V$30,"Neutral") -> 3 | E9: =COUNTIF('Raw Data'!$V$2:$V$30,"Need More Knowledge") -> 1 | F9: =COUNTIF('Raw Data'!$V$2:$V$30,"Not Confident") -> 0 | G9: =IFERROR((B9*4+C9*3+D9*2+(E9+F9)*1)/COUNTA('Raw Data'!$V$2:$V$30),0) -> 3.2068966 | H9: =IFERROR((D9+E9+F9)/COUNTA('Raw Data'!$V$2:$V$30),0) -> 0.13793103 | I9: =IF(H9>=0.6,"Critical",IF(H9>=0.4,"High",IF(H9>=0.2,"Medium","Low"))) -> Low
A10: LPCO Processing | B10: =COUNTIF('Raw Data'!$W$2:$W$30,"Very Confident") -> 15 | C10: =COUNTIF('Raw Data'!$W$2:$W$30,"Confident") -> 11 | D10: =COUNTIF('Raw Data'!$W$2:$W$30,"Neutral") -> 3 | E10: =COUNTIF('Raw Data'!$W$2:$W$30,"Need More Knowledge") -> 0 | F10: =COUNTIF('Raw Data'!$W$2:$W$30,"Not Confident") -> 0 | G10: =IFERROR((B10*4+C10*3+D10*2+(E10+F10)*1)/COUNTA('Raw Data'!$W$2:$W$30),0) -> 3.4137931 | H10: =IFERROR((D10+E10+F10)/COUNTA('Raw Data'!$W$2:$W$30),0) -> 0.10344828 | I10: =IF(H10>=0.6,"Critical",IF(H10>=0.4,"High",IF(H10>=0.2,"Medium","Low"))) -> Low
A11: Air Manifest | B11: =COUNTIF('Raw Data'!$X$2:$X$30,"Very Confident") -> 0 | C11: =COUNTIF('Raw Data'!$X$2:$X$30,"Confident") -> 1 | D11: =COUNTIF('Raw Data'!$X$2:$X$30,"Neutral") -> 11 | E11: =COUNTIF('Raw Data'!$X$2:$X$30,"Need More Knowledge") -> 14 | F11: =COUNTIF('Raw Data'!$X$2:$X$30,"Not Confident") -> 3 | G11: =IFERROR((B11*4+C11*3+D11*2+(E11+F11)*1)/COUNTA('Raw Data'!$X$2:$X$30),0) -> 1.4482759 | H11: =IFERROR((D11+E11+F11)/COUNTA('Raw Data'!$X$2:$X$30),0) -> 0.96551724 | I11: =IF(H11>=0.6,"Critical",IF(H11>=0.4,"High",IF(H11>=0.2,"Medium","Low"))) -> Critical
A12: Sea Manifest | B12: =COUNTIF('Raw Data'!$Y$2:$Y$30,"Very Confident") -> 0 | C12: =COUNTIF('Raw Data'!$Y$2:$Y$30,"Confident") -> 1 | D12: =COUNTIF('Raw Data'!$Y$2:$Y$30,"Neutral") -> 10 | E12: =COUNTIF('Raw Data'!$Y$2:$Y$30,"Need More Knowledge") -> 15 | F12: =COUNTIF('Raw Data'!$Y$2:$Y$30,"Not Confident") -> 3 | G12: =IFERROR((B12*4+C12*3+D12*2+(E12+F12)*1)/COUNTA('Raw Data'!$Y$2:$Y$30),0) -> 1.4137931 | H12: =IFERROR((D12+E12+F12)/COUNTA('Raw Data'!$Y$2:$Y$30),0) -> 0.96551724 | I12: =IF(H12>=0.6,"Critical",IF(H12>=0.4,"High",IF(H12>=0.2,"Medium","Low"))) -> Critical

Sheet Individual Analysis
A1: Name | B1: Tenure | C1: User Registration | D1: Login & Authentication | E1: UCR | F1: Facility Registration | G1: Application Submission | H1: Payment | I1: Certificate Utilization | J1: Form M / PAAR Processing | K1: LPCO Processing | L1: Air Manifest | M1: Sea Manifest | N1: Average Confidence Score | O1: Number of Gap Modules | P1: Gap % | Q1: Overall Flag
A2: ='Raw Data'!A2 -> Atuke Onoriode | B2: ='Raw Data'!C2 -> 6–12 months | C2: ='Raw Data'!O2 -> Very Confident | D2: ='Raw Data'!P2 -> Very Confident | E2: ='Raw Data'!Q2 -> Very Confident | F2: ='Raw Data'!R2 -> Very Confident | G2: ='Raw Data'!S2 -> Very Confident | H2: ='Raw Data'!T2 -> Very Confident | I2: ='Raw Data'!U2 -> Very Confident | J2: ='Raw Data'!V2 -> Very Confident | ... M2: ='Raw Data'!Y2 -> Neutral | N2: =AVERAGE(IF(C2="Very Confident",4,IF(C2="Confident",3,IF(C2="Neutral",2,IF(OR(C2="Need More Knowledge",C2="Not Confident"),1,0)))),IF(D2="Very Confident",4,IF(D2="Confident",3,IF(D2="Neutral",2,IF(OR(D2="Need More Knowledge",D2="Not Confident"),1,0)))),IF(E2="Very Confident",4,IF(E2="Confident",3,IF(E2="Neutral",2,IF(OR(E2="Need More Knowledge",E2="Not Confident"),1,0)))),IF(F2="Very Confident",4,IF(F2="Confident",3,IF(F2="Neutral",2,IF(OR(F2="Need More Knowledge",F2="Not Confident"),1,0)))),IF(G2="Very Confident",4,IF(G2="Confident",3,IF(G2="Neutral",2,IF(OR(G2="Need More Knowledge",G2="Not Confident"),1,0)))),IF(H2="Very Confident",4,IF(H2="Confident",3,IF(H2="Neutral",2,IF(OR(H2="Need More Knowledge",H2="Not Confident"),1,0)))),IF(I2="Very Confident",4,IF(I2="Confident",3,IF(I2="Neutral",2,IF(OR(I2="Need More Knowledge",I2="Not Confident"),1,0)))),IF(J2="Very Confident",4,IF(J2="Confident",3,IF(J2="Neutral",2,IF(OR(J2="Need More Knowledge",J2="Not Confident"),1,0)))),IF(K2="Very Confident",4,IF(K2="Confident",3,IF(K2="Neutral",2,IF(OR(K2="Need More Knowledge",K2="Not Confident"),1,0)))),IF(L2="Very Confident",4,IF(L2="Confident",3,IF(L2="Neutral",2,IF(OR(L2="Need More Knowledge",L2="Not Confident"),1,0)))),IF(M2="Very Confident",4,IF(M2="Confident",3,IF(M2="Neutral",2,IF(OR(M2="Need More Knowledge",M2="Not Confident"),1,0))))) -> 3.6363636 | O2: =SUM(IF(OR(C2="Neutral",C2="Need More Knowledge",C2="Not Confident"),1,0),IF(OR(D2="Neutral",D2="Need More Knowledge",D2="Not Confident"),1,0),IF(OR(E2="Neutral",E2="Need More Knowledge",E2="Not Confident"),1,0),IF(OR(F2="Neutral",F2="Need More Knowledge",F2="Not Confident"),1,0),IF(OR(G2="Neutral",G2="Need More Knowledge",G2="Not Confident"),1,0),IF(OR(H2="Neutral",H2="Need More Knowledge",H2="Not Confident"),1,0),IF(OR(I2="Neutral",I2="Need More Knowledge",I2="Not Confident"),1,0),IF(OR(J2="Neutral",J2="Need More Knowledge",J2="Not Confident"),1,0),IF(OR(K2="Neutral",K2="Need More Knowledge",K2="Not Confident"),1,0),IF(OR(L2="Neutral",L2="Need More Knowledge",L2="Not Confident"),1,0),IF(OR(M2="Neutral",M2="Need More Knowledge",M2="Not Confident"),1,0)) -> 2 | P2: =O2/11 -> 0.18181818 | Q2: =IF(P2>=0.4,"High Gap",IF(P2>=0.2,"Moderate Gap","Low Gap")) -> Low Gap
A3: ='Raw Data'!A3 -> Ifechukwu Ozuluonye | B3: ='Raw Data'!C3 -> 3–6 months | C3: ='Raw Data'!O3 -> Very Confident | D3: ='Raw Data'!P3 -> Very Confident | E3: ='Raw Data'!Q3 -> Very Confident | F3: ='Raw Data'!R3 -> Very Confident | G3: ='Raw Data'!S3 -> Very Confident | H3: ='Raw Data'!T3 -> Very Confident | I3: ='Raw Data'!U3 -> Very Confident | J3: ='Raw Data'!V3 -> Confident | ... M3: ='Raw Data'!Y3 -> Neutral | N3: =AVERAGE(IF(C3="Very Confident",4,IF(C3="Confident",3,IF(C3="Neutral",2,IF(OR(C3="Need More Knowledge",C3="Not Confident"),1,0)))),IF(D3="Very Confident",4,IF(D3="Confident",3,IF(D3="Neutral",2,IF(OR(D3="Need More Knowledge",D3="Not Confident"),1,0)))),IF(E3="Very Confident",4,IF(E3="Confident",3,IF(E3="Neutral",2,IF(OR(E3="Need More Knowledge",E3="Not Confident"),1,0)))),IF(F3="Very Confident",4,IF(F3="Confident",3,IF(F3="Neutral",2,IF(OR(F3="Need More Knowledge",F3="Not Confident"),1,0)))),IF(G3="Very Confident",4,IF(G3="Confident",3,IF(G3="Neutral",2,IF(OR(G3="Need More Knowledge",G3="Not Confident"),1,0)))),IF(H3="Very Confident",4,IF(H3="Confident",3,IF(H3="Neutral",2,IF(OR(H3="Need More Knowledge",H3="Not Confident"),1,0)))),IF(I3="Very Confident",4,IF(I3="Confident",3,IF(I3="Neutral",2,IF(OR(I3="Need More Knowledge",I3="Not Confident"),1,0)))),IF(J3="Very Confident",4,IF(J3="Confident",3,IF(J3="Neutral",2,IF(OR(J3="Need More Knowledge",J3="Not Confident"),1,0)))),IF(K3="Very Confident",4,IF(K3="Confident",3,IF(K3="Neutral",2,IF(OR(K3="Need More Knowledge",K3="Not Confident"),1,0)))),IF(L3="Very Confident",4,IF(L3="Confident",3,IF(L3="Neutral",2,IF(OR(L3="Need More Knowledge",L3="Not Confident"),1,0)))),IF(M3="Very Confident",4,IF(M3="Confident",3,IF(M3="Neutral",2,IF(OR(M3="Need More Knowledge",M3="Not Confident"),1,0))))) -> 3.4545455 | O3: =SUM(IF(OR(C3="Neutral",C3="Need More Knowledge",C3="Not Confident"),1,0),IF(OR(D3="Neutral",D3="Need More Knowledge",D3="Not Confident"),1,0),IF(OR(E3="Neutral",E3="Need More Knowledge",E3="Not Confident"),1,0),IF(OR(F3="Neutral",F3="Need More Knowledge",F3="Not Confident"),1,0),IF(OR(G3="Neutral",G3="Need More Knowledge",G3="Not Confident"),1,0),IF(OR(H3="Neutral",H3="Need More Knowledge",H3="Not Confident"),1,0),IF(OR(I3="Neutral",I3="Need More Knowledge",I3="Not Confident"),1,0),IF(OR(J3="Neutral",J3="Need More Knowledge",J3="Not Confident"),1,0),IF(OR(K3="Neutral",K3="Need More Knowledge",K3="Not Confident"),1,0),IF(OR(L3="Neutral",L3="Need More Knowledge",L3="Not Confident"),1,0),IF(OR(M3="Neutral",M3="Need More Knowledge",M3="Not Confident"),1,0)) -> 2 | P3: =O3/11 -> 0.18181818 | Q3: =IF(P3>=0.4,"High Gap",IF(P3>=0.2,"Moderate Gap","Low Gap")) -> Low Gap
A4: ='Raw Data'!A4 -> Thelma Ozichi | B4: ='Raw Data'!C4 -> 3–6 months | C4: ='Raw Data'!O4 -> Very Confident | D4: ='Raw Data'!P4 -> Very Confident | E4: ='Raw Data'!Q4 -> Very Confident | F4: ='Raw Data'!R4 -> Very Confident | G4: ='Raw Data'!S4 -> Very Confident | H4: ='Raw Data'!T4 -> Very Confident | I4: ='Raw Data'!U4 -> Very Confident | J4: ='Raw Data'!V4 -> Very Confident | ... M4: ='Raw Data'!Y4 -> Need More Knowledge | N4: =AVERAGE(IF(C4="Very Confident",4,IF(C4="Confident",3,IF(C4="Neutral",2,IF(OR(C4="Need More Knowledge",C4="Not Confident"),1,0)))),IF(D4="Very Confident",4,IF(D4="Confident",3,IF(D4="Neutral",2,IF(OR(D4="Need More Knowledge",D4="Not Confident"),1,0)))),IF(E4="Very Confident",4,IF(E4="Confident",3,IF(E4="Neutral",2,IF(OR(E4="Need More Knowledge",E4="Not Confident"),1,0)))),IF(F4="Very Confident",4,IF(F4="Confident",3,IF(F4="Neutral",2,IF(OR(F4="Need More Knowledge",F4="Not Confident"),1,0)))),IF(G4="Very Confident",4,IF(G4="Confident",3,IF(G4="Neutral",2,IF(OR(G4="Need More Knowledge",G4="Not Confident"),1,0)))),IF(H4="Very Confident",4,IF(H4="Confident",3,IF(H4="Neutral",2,IF(OR(H4="Need More Knowledge",H4="Not Confident"),1,0)))),IF(I4="Very Confident",4,IF(I4="Confident",3,IF(I4="Neutral",2,IF(OR(I4="Need More Knowledge",I4="Not Confident"),1,0)))),IF(J4="Very Confident",4,IF(J4="Confident",3,IF(J4="Neutral",2,IF(OR(J4="Need More Knowledge",J4="Not Confident"),1,0)))),IF(K4="Very Confident",4,IF(K4="Confident",3,IF(K4="Neutral",2,IF(OR(K4="Need More Knowledge",K4="Not Confident"),1,0)))),IF(L4="Very Confident",4,IF(L4="Confident",3,IF(L4="Neutral",2,IF(OR(L4="Need More Knowledge",L4="Not Confident"),1,0)))),IF(M4="Very Confident",4,IF(M4="Confident",3,IF(M4="Neutral",2,IF(OR(M4="Need More Knowledge",M4="Not Confident"),1,0))))) -> 3.4545455 | O4: =SUM(IF(OR(C4="Neutral",C4="Need More Knowledge",C4="Not Confident"),1,0),IF(OR(D4="Neutral",D4="Need More Knowledge",D4="Not Confident"),1,0),IF(OR(E4="Neutral",E4="Need More Knowledge",E4="Not Confident"),1,0),IF(OR(F4="Neutral",F4="Need More Knowledge",F4="Not Confident"),1,0),IF(OR(G4="Neutral",G4="Need More Knowledge",G4="Not Confident"),1,0),IF(OR(H4="Neutral",H4="Need More Knowledge",H4="Not Confident"),1,0),IF(OR(I4="Neutral",I4="Need More Knowledge",I4="Not Confident"),1,0),IF(OR(J4="Neutral",J4="Need More Knowledge",J4="Not Confident"),1,0),IF(OR(K4="Neutral",K4="Need More Knowledge",K4="Not Confident"),1,0),IF(OR(L4="Neutral",L4="Need More Knowledge",L4="Not Confident"),1,0),IF(OR(M4="Neutral",M4="Need More Knowledge",M4="Not Confident"),1,0)) -> 2 | P4: =O4/11 -> 0.18181818 | Q4: =IF(P4>=0.4,"High Gap",IF(P4>=0.2,"Moderate Gap","Low Gap")) -> Low Gap
A5: ='Raw Data'!A5 -> Queen Ugbebor | B5: ='Raw Data'!C5 -> 3–6 months | C5: ='Raw Data'!O5 -> Very Confident | D5: ='Raw Data'!P5 -> Very Confident | E5: ='Raw Data'!Q5 -> Very Confident | F5: ='Raw Data'!R5 -> Very Confident | G5: ='Raw Data'!S5 -> Very Confident | H5: ='Raw Data'!T5 -> Neutral | I5: ='Raw Data'!U5 -> Neutral | J5: ='Raw Data'!V5 -> Very Confident | ... M5: ='Raw Data'!Y5 -> Not Confident | N5: =AVERAGE(IF(C5="Very Confident",4,IF(C5="Confident",3,IF(C5="Neutral",2,IF(OR(C5="Need More Knowledge",C5="Not Confident"),1,0)))),IF(D5="Very Confident",4,IF(D5="Confident",3,IF(D5="Neutral",2,IF(OR(D5="Need More Knowledge",D5="Not Confident"),1,0)))),IF(E5="Very Confident",4,IF(E5="Confident",3,IF(E5="Neutral",2,IF(OR(E5="Need More Knowledge",E5="Not Confident"),1,0)))),IF(F5="Very Confident",4,IF(F5="Confident",3,IF(F5="Neutral",2,IF(OR(F5="Need More Knowledge",F5="Not Confident"),1,0)))),IF(G5="Very Confident",4,IF(G5="Confident",3,IF(G5="Neutral",2,IF(OR(G5="Need More Knowledge",G5="Not Confident"),1,0)))),IF(H5="Very Confident",4,IF(H5="Confident",3,IF(H5="Neutral",2,IF(OR(H5="Need More Knowledge",H5="Not Confident"),1,0)))),IF(I5="Very Confident",4,IF(I5="Confident",3,IF(I5="Neutral",2,IF(OR(I5="Need More Knowledge",I5="Not Confident"),1,0)))),IF(J5="Very Confident",4,IF(J5="Confident",3,IF(J5="Neutral",2,IF(OR(J5="Need More Knowledge",J5="Not Confident"),1,0)))),IF(K5="Very Confident",4,IF(K5="Confident",3,IF(K5="Neutral",2,IF(OR(K5="Need More Knowledge",K5="Not Confident"),1,0)))),IF(L5="Very Confident",4,IF(L5="Confident",3,IF(L5="Neutral",2,IF(OR(L5="Need More Knowledge",L5="Not Confident"),1,0)))),IF(M5="Very Confident",4,IF(M5="Confident",3,IF(M5="Neutral",2,IF(OR(M5="Need More Knowledge",M5="Not Confident"),1,0))))) -> 3.0909091 | O5: =SUM(IF(OR(C5="Neutral",C5="Need More Knowledge",C5="Not Confident"),1,0),IF(OR(D5="Neutral",D5="Need More Knowledge",D5="Not Confident"),1,0),IF(OR(E5="Neutral",E5="Need More Knowledge",E5="Not Confident"),1,0),IF(OR(F5="Neutral",F5="Need More Knowledge",F5="Not Confident"),1,0),IF(OR(G5="Neutral",G5="Need More Knowledge",G5="Not Confident"),1,0),IF(OR(H5="Neutral",H5="Need More Knowledge",H5="Not Confident"),1,0),IF(OR(I5="Neutral",I5="Need More Knowledge",I5="Not Confident"),1,0),IF(OR(J5="Neutral",J5="Need More Knowledge",J5="Not Confident"),1,0),IF(OR(K5="Neutral",K5="Need More Knowledge",K5="Not Confident"),1,0),IF(OR(L5="Neutral",L5="Need More Knowledge",L5="Not Confident"),1,0),IF(OR(M5="Neutral",M5="Need More Knowledge",M5="Not Confident"),1,0)) -> 4 | P5: =O5/11 -> 0.36363636 | Q5: =IF(P5>=0.4,"High Gap",IF(P5>=0.2,"Moderate Gap","Low Gap")) -> Moderate Gap
